import { StackAssertionError, captureError } from "./errors";
import { DependenciesMap } from "./maps";
import { Result } from "./results";
import { generateUuid } from "./uuids";

export type ReactPromise<T> = Promise<T> & (
  | { status: "rejected", reason: unknown }
  | { status: "fulfilled", value: T }
  | { status: "pending" }
);

type Resolve<T> = (value: T) => void;
type Reject = (reason: unknown) => void;
export function createPromise<T>(callback: (resolve: Resolve<T>, reject: Reject) => void): ReactPromise<T> {
  let status = "pending" as "fulfilled" | "rejected" | "pending";
  let valueOrReason: T | unknown | undefined = undefined;
  let resolve: Resolve<T> | null = null;
  let reject: Reject | null = null;
  const promise = new Promise<T>((res, rej) => {
    resolve = (value) => {
      if (status !== "pending") return;
      status = "fulfilled";
      valueOrReason = value;
      res(value);
    };
    reject = (reason) => {
      if (status !== "pending") return;
      status = "rejected";
      valueOrReason = reason;
      rej(reason);
    };
  });

  callback(resolve!, reject!);
  return Object.assign(promise, {
    status: status,
    ...status === "fulfilled" ? { value: valueOrReason as T } : {},
    ...status === "rejected" ? { reason: valueOrReason } : {},
  } as any);
}

const resolvedCache = new DependenciesMap<[unknown], ReactPromise<unknown>>();
/**
 * Like Promise.resolve(...), but also adds the status and value properties for use with React's `use` hook, and caches
 * the value so that invoking `resolved` twice returns the same promise.
 */
export function resolved<T>(value: T): ReactPromise<T> {
  if (resolvedCache.has([value])) {
    return resolvedCache.get([value]) as ReactPromise<T>;
  }

  const res = Object.assign(Promise.resolve(value), {
    status: "fulfilled",
    value,
  } as const);
  resolvedCache.set([value], res);
  return res;
}

const rejectedCache = new DependenciesMap<[unknown], ReactPromise<unknown>>();
/**
 * Like Promise.reject(...), but also adds the status and value properties for use with React's `use` hook, and caches
 * the value so that invoking `rejected` twice returns the same promise.
 */
export function rejected<T>(reason: unknown): ReactPromise<T> {
  if (rejectedCache.has([reason])) {
    return rejectedCache.get([reason]) as ReactPromise<T>;
  }

  const res = Object.assign(Promise.reject(reason), {
    status: "rejected",
    reason: reason,
  } as const);
  rejectedCache.set([reason], res);
  return res;
}

const neverResolvePromise = pending(new Promise<never>(() => {}));
export function neverResolve(): ReactPromise<never> {
  return neverResolvePromise;
}

export function pending<T>(promise: Promise<T>, options: { disableErrorWrapping?: boolean } = {}): ReactPromise<T> {
  const res = promise.then(
    value => {
      res.status = "fulfilled";
      (res as any).value = value;
      return value;
    },
    actualReason => {
      res.status = "rejected";
      (res as any).reason = actualReason;
      throw actualReason;
    },
  ) as ReactPromise<T>;
  res.status = "pending";
  return res;
}

/**
 * Should be used to wrap Promises that are not immediately awaited, so they don't throw an unhandled promise rejection
 * error.
 *
 * Vercel kills serverless functions on unhandled promise rejection errors, so this is important.
 */
export function ignoreUnhandledRejection<T extends Promise<any>>(promise: T): T {
  promise.catch(() => {});
  return promise;
}

export async function wait(ms: number) {
  if (!Number.isFinite(ms) || ms < 0) {
    throw new StackAssertionError(`wait() requires a non-negative integer number of milliseconds to wait. (found: ${ms}ms)`);
  }
  if (ms >= 2**31) {
    throw new StackAssertionError("The maximum timeout for wait() is 2147483647ms (2**31 - 1). (found: ${ms}ms)");
  }
  return await new Promise<void>(resolve => setTimeout(resolve, ms));
}

export async function waitUntil(date: Date) {
  return await wait(date.getTime() - Date.now());
}

class ErrorDuringRunAsynchronously extends Error {
  constructor() {
    super("The error above originated in a runAsynchronously() call. Here is the stacktrace associated with it.");
    this.name = "ErrorDuringRunAsynchronously";
  }
}

export function runAsynchronouslyWithAlert(...args: Parameters<typeof runAsynchronously>) {
  return runAsynchronously(
    args[0],
    {
      ...args[1],
      onError: error => {
        alert(`An unhandled error occurred. Please ${process.env.NODE_ENV === "development" ? `check the browser console for the full error. ${error}` : "report this to the developer."}\n\n${error}`);
        args[1]?.onError?.(error);
      },
    },
    ...args.slice(2) as [],
  );
}

export function runAsynchronously(
  promiseOrFunc: void | Promise<unknown> | (() => void | Promise<unknown>) | undefined,
  options: {
    noErrorLogging?: boolean,
    onError?: (error: Error) => void,
  } = {},
): void {
  if (typeof promiseOrFunc === "function") {
    promiseOrFunc = promiseOrFunc();
  }
  const duringError = new ErrorDuringRunAsynchronously();
  promiseOrFunc?.catch(error => {
    const newError = new StackAssertionError(
      "Uncaught error in asynchronous function: " + error.toString(),
      {
        duringError,
      },
      {
        cause: error,
      }
    );
    options.onError?.(newError);
    if (!options.noErrorLogging) {
      captureError("runAsynchronously", newError);
    }
  });
}


class TimeoutError extends Error {
  constructor(public readonly ms: number) {
    super(`Timeout after ${ms}ms`);
    this.name = "TimeoutError";
  }
}

export async function timeout<T>(promise: Promise<T>, ms: number): Promise<Result<T, TimeoutError>> {
  return await Promise.race([
    promise.then(value => Result.ok(value)),
    wait(ms).then(() => Result.error(new TimeoutError(ms))),
  ]);
}

export async function timeoutThrow<T>(promise: Promise<T>, ms: number): Promise<T> {
  return Result.orThrow(await timeout(promise, ms));
}


export type RateLimitOptions = {
  /**
   * The number of requests to process in parallel. Currently only 1 is supported.
   */
  concurrency: 1,

  /**
   * If true, multiple requests waiting at the same time will be reduced to just one. Default is false.
   */
  batchCalls?: boolean,

  /**
   * Waits for throttleMs since the start of last request before starting the next request. Default is 0.
   */
  throttleMs?: number,

  /**
   * Waits for gapMs since the end of last request before starting the next request. Default is 0.
   */
  gapMs?: number,

  /**
   * Waits until there have been no new requests for debounceMs before starting a new request. Default is 0.
   */
  debounceMs?: number,
};

export function rateLimited<T>(
  func: () => Promise<T>,
  options: RateLimitOptions,
): () => Promise<T> {
  let waitUntil = performance.now();
  let queue: [(t: T) => void, (e: unknown) => void][] = [];
  let addedToQueueCallbacks = new Map<string, () => void>;

  const next = async () => {
    while (true) {
      if (waitUntil > performance.now()) {
        await wait(Math.max(1, waitUntil - performance.now() + 1));
      } else if (queue.length === 0) {
        const uuid = generateUuid();
        await new Promise<void>(resolve => {
          addedToQueueCallbacks.set(uuid, resolve);
        });
        addedToQueueCallbacks.delete(uuid);
      } else {
        break;
      }
    }
    const nextFuncs = options.batchCalls ? queue.splice(0, queue.length) : [queue.shift()!];

    const start = performance.now();
    const value = await Result.fromPromise(func());
    const end = performance.now();

    waitUntil = Math.max(
      waitUntil,
      start + (options.throttleMs ?? 0),
      end + (options.gapMs ?? 0),
    );

    for (const nextFunc of nextFuncs) {
      if (value.status === "ok") {
        nextFunc[0](value.data);
      } else {
        nextFunc[1](value.error);
      }
    }
  };

  runAsynchronously(async () => {
    while (true) {
      await next();
    }
  });

  return () => {
    return new Promise<T>((resolve, reject) => {
      waitUntil = Math.max(
        waitUntil,
        performance.now() + (options.debounceMs ?? 0),
      );
      queue.push([resolve, reject]);
      addedToQueueCallbacks.forEach(cb => cb());
    });
  };
}

export function throttled<T, A extends any[]>(func: (...args: A) => Promise<T>, delayMs: number): (...args: A) => Promise<T> {
  let timeout: ReturnType<typeof setTimeout> | null = null;
  let nextAvailable: Promise<T> | null = null;
  return async (...args) => {
    while (nextAvailable !== null) {
      await nextAvailable;
    }
    nextAvailable = new Promise<T>(resolve => {
      timeout = setTimeout(() => {
        nextAvailable = null;
        resolve(func(...args));
      }, delayMs);
    });
    return await nextAvailable;
  };
}
